Workbook
Name BusinessValueTable: '8. Scoring Guidelines'!$B$5:$E$11
Name BusinessValueTerms: '8. Scoring Guidelines'!$B$5:$B$11

Sheet 1. Dashboard
A1: BNZ AI USE CASE PRIORITIZATION DASHBOARD
A3: SUMMARY STATISTICS | D3: TOP 10 USE CASES (BY WSJF RANK)
A4: Total Use Cases: | B4: =COUNTA('2. Use Cases'!A2:A25) -> 24 | D4: Rank | E4: ID | F4: Name
A5: DVF Pass: | B5: =COUNTIF('3. DVF Filtering'!G2:G25,"Pass") -> 0 | D5: =1 -> 1
A6: DVF Fail: | B6: =COUNTIF('3. DVF Filtering'!G2:G25,"Fail") -> 23 | D6: =2 -> 2
A7: Top 10 Count: | B7: =COUNTIF('6. Portfolio View'!J2:J25,TRUE) -> 0 | D7: =3 -> 3
A8: Top 5 Count: | B8: =COUNTIF('6. Portfolio View'!K2:K25,TRUE) -> 0 | D8: =4 -> 4
A9: Wave 1 Use Cases: | B9: =COUNTIF('5. Dependencies Schedule'!G2:G25,"Wave 1") -> 0 | D9: =5 -> 5
A10: Wave 2 Use Cases: | B10: =COUNTIF('5. Dependencies Schedule'!G2:G25,"Wave 2") -> 0 | D10: =6 -> 6
A11: Wave 3 Use Cases: | B11: =COUNTIF('5. Dependencies Schedule'!G2:G25,"Wave 3") -> 0 | D11: =7 -> 7
D12: =8 -> 8
A13: PORTFOLIO QUADRANTS | D13: =9 -> 9
A14: Quick Wins: | B14: =COUNTIF('6. Portfolio View'!H2:H25,"Quick Win") -> 0 | D14: =10 -> 10
A15: Strategic Bets: | B15: =COUNTIF('6. Portfolio View'!H2:H25,"Strategic Bet") -> 0
A16: Fill-ins: | B16: =COUNTIF('6. Portfolio View'!H2:H25,"Fill-in") -> 0
A17: Avoid: | B17: =COUNTIF('6. Portfolio View'!H2:H25,"Avoid") -> 23

Sheet 2. Use Cases
A1: ID | B1: Name | C1: Summary | D1: Opportunity | E1: Business Value | F1: Benefits
A2: UC01 | B2: FrontLine - Partnership Banking | C2: GenAI-driven RM solutions for deepening banker-customer relationships. | D2: Increased revenue through improved cross-sell / upsell effectiveness; Enhanced customer satisfaction and retention; Reduced relationship manager preparation time; Improved customer lifetime value; Better risk identification and proactive engagement. | E2: Moderate | F2: =VLOOKUP(use_cases[[#This Row],[Business Value]],BusinessValueTable,3,FALSE) -> $100K-500K benefit OR 2-5% efficiency
A3: UC02 | B3: Finance | C3: Transform raw financial data into well-structured reports (P&L, balance sheets). | D3: Reduced month-end close time; Improved accuracy and reduced manual errors; Faster decision-making with real-time insights; Enhanced regulatory compliance; Reduced FTE costs in financial reporting. | E3: Moderate | F3: =VLOOKUP(use_cases[[#This Row],[Business Value]],BusinessValueTable,3,FALSE) -> $100K-500K benefit OR 2-5% efficiency
A4: UC03 | B4: Analytics and Reporting | C4: AI builds on BI by turning historical data into proactive guidance. | D4: Democratized data access reducing analyst dependency; Proactive decision-making with predictive capabilities; Reduced report generation time from days to minutes; Improved business agility and responsiveness; Enhanced data-driven culture across organization. | E4: Moderate | F4: =VLOOKUP(use_cases[[#This Row],[Business Value]],BusinessValueTable,3,FALSE) -> $100K-500K benefit OR 2-5% efficiency
A5: UC04 | B5: Credit Risk | C5: GenAI-driven Credit Risk solutions for data-driven decision-making. | D5: Reduced credit losses through better risk assessment; Faster loan approval times improving customer experience; Optimized pricing increasing profitability; Enhanced portfolio monitoring reducing defaults; Improved regulatory compliance and capital efficiency. | E5: Moderate | F5: =VLOOKUP(use_cases[[#This Row],[Business Value]],BusinessValueTable,3,FALSE) -> $100K-500K benefit OR 2-5% efficiency
A6: UC05 | B6: Lending Ops | C6: AI Document Processing for Loan Applications & Compliance. | D6: Processing time reduction for loan applications; Improved accuracy reducing rework; Enhanced compliance with automated validation; Reduced operational costs; Faster time-to-yes improving customer satisfaction | E6: Moderate | F6: =VLOOKUP(use_cases[[#This Row],[Business Value]],BusinessValueTable,3,FALSE) -> $100K-500K benefit OR 2-5% efficiency
A7: UC06 | B7: HyperPersonalization | C7: Generative AI enables new customer relevance through marketing reinvention. | D7: Increased campaign conversion rates; Higher customer engagement and satisfaction scores; Improved product adoption; Reduced customer churn; Enhanced brand loyalty and NPS scores | E7: Moderate | F7: =VLOOKUP(use_cases[[#This Row],[Business Value]],BusinessValueTable,3,FALSE) -> $100K-500K benefit OR 2-5% efficiency
A8: UC07 | B8: Contact Centre | C8: Generate call summaries, agent-assist features, customer self-service. | D8: Reduced average handle time; Improved first call resolution; Enhanced customer satisfaction (CSAT) scores; Reduced agent training time; Lower operational costs through automation of inquiries | E8: Moderate | F8: =VLOOKUP(use_cases[[#This Row],[Business Value]],BusinessValueTable,3,FALSE) -> $100K-500K benefit OR 2-5% efficiency
A9: UC08 | B9: Security AI | C9: Use of AI to identify threats earlier with higher accuracy. | D9: Reduced threat detection time from hours to minutes; reduction in false positives; Prevented potential losses from cyber attacks; Enhanced regulatory compliance and risk management; Improved security team efficiency. | E9: Moderate | F9: =VLOOKUP(use_cases[[#This Row],[Business Value]],BusinessValueTable,3,FALSE) -> $100K-500K benefit OR 2-5% efficiency
A10: UC09 | B10: Data Products | C10: Extend GenAI intervention to accelerate data product creation. | D10: Accelerated data product delivery; Improved data quality and consistency; Enhanced data discoverability and reusability; Reduced time-to-insight for business users; Lower data engineering costs. | E10: Moderate | F10: =VLOOKUP(use_cases[[#This Row],[Business Value]],BusinessValueTable,3,FALSE) -> $100K-500K benefit OR 2-5% efficiency
A11: UC10 | B11: SDLC | C11: GenAI can automate key SDLC tasks, enhancing productivity. | D11: Developer productivity increased; Faster time-to-market; Reduced bugs and security vulnerabilities; Improved code quality and maintainability; Lower technical debt accumulation. | E11: Moderate | F11: =VLOOKUP(use_cases[[#This Row],[Business Value]],BusinessValueTable,3,FALSE) -> $100K-500K benefit OR 2-5% efficiency
A12: UC11 | B12: Fincrime | C12: Name screening, OCDD, ECDD and TM narrative writing. | D12: Reduced investigation time; Improved detection accuracy reducing false positives; Enhanced regulatory compliance and audit readiness; Lower operational costs; Faster filing and response times. | E12: Moderate | F12: =VLOOKUP(use_cases[[#This Row],[Business Value]],BusinessValueTable,3,FALSE) -> $100K-500K benefit OR 2-5% efficiency
A13: UC12 | B13: QA/QC | C13: Automate data validation, detecting errors, ensuring compliance. | D13: Reduced manual QA effort; Improved data quality and accuracy; Faster identification of high-risk issues; Enhanced regulatory compliance; Lower operational risk and audit findings. | E13: Moderate | F13: =VLOOKUP(use_cases[[#This Row],[Business Value]],BusinessValueTable,3,FALSE) -> $100K-500K benefit OR 2-5% efficiency
... A25: UC24 | B25: Front-end App Personalisation | C25: Use of GenAI in mobile app for hyper personalisation. | D25: Increased app engagement; Higher product adoption through personalized recommendations; Improved NPS and customer satisfaction scores; Reduced marketing campaign costs; Enhanced brand differentiation with Uber-like experience. | E25: Moderate | F25: =VLOOKUP(use_cases[[#This Row],[Business Value]],BusinessValueTable,3,FALSE) -> $100K-500K benefit OR 2-5% efficiency

Sheet 3. DVF Filtering
A1: INSTRUCTIONS: Score each dimension 1-5. Pass requires ALL dimensions ≥3. 5=Excellent, 4=Good, 3=Acceptable, 2=Poor, 1=Very Poor
A2: ID | B2: Name | C2: Desirability (1-5) | D2: Viability (1-5) | E2: Feasibility (1-5) | F2: DVF Total | G2: DVF Status | H2: Notes
A3: UC01 | B3: =VLOOKUP(DVF_Filtering[[#This Row],[ID]],'2. Use Cases'!A:B,2,FALSE) -> FrontLine - Partnership Banking | C3: 1 | D3: 1 | E3: 1 | F3: =SUM(DVF_Filtering[[#This Row],[Desirability (1-5)]:[Feasibility (1-5)]]) -> 3 | G3: =IF(AND(C3>=3,D3>=3,E3>=3),"Pass","Fail") -> Fail
A4: UC02 | B4: =VLOOKUP(DVF_Filtering[[#This Row],[ID]],'2. Use Cases'!A:B,2,FALSE) -> Finance | C4: 1 | D4: 1 | E4: 1 | F4: =SUM(DVF_Filtering[[#This Row],[Desirability (1-5)]:[Feasibility (1-5)]]) -> 3 | G4: =IF(AND(C4>=3,D4>=3,E4>=3),"Pass","Fail") -> Fail
A5: UC03 | B5: =VLOOKUP(DVF_Filtering[[#This Row],[ID]],'2. Use Cases'!A:B,2,FALSE) -> Analytics and Reporting | C5: 1 | D5: 1 | E5: 1 | F5: =SUM(DVF_Filtering[[#This Row],[Desirability (1-5)]:[Feasibility (1-5)]]) -> 3 | G5: =IF(AND(C5>=3,D5>=3,E5>=3),"Pass","Fail") -> Fail
A6: UC04 | B6: =VLOOKUP(DVF_Filtering[[#This Row],[ID]],'2. Use Cases'!A:B,2,FALSE) -> Credit Risk | C6: 1 | D6: 1 | E6: 1 | F6: =SUM(DVF_Filtering[[#This Row],[Desirability (1-5)]:[Feasibility (1-5)]]) -> 3 | G6: =IF(AND(C6>=3,D6>=3,E6>=3),"Pass","Fail") -> Fail
A7: UC05 | B7: =VLOOKUP(DVF_Filtering[[#This Row],[ID]],'2. Use Cases'!A:B,2,FALSE) -> Lending Ops | C7: 1 | D7: 1 | E7: 1 | F7: =SUM(DVF_Filtering[[#This Row],[Desirability (1-5)]:[Feasibility (1-5)]]) -> 3 | G7: =IF(AND(C7>=3,D7>=3,E7>=3),"Pass","Fail") -> Fail
A8: UC06 | B8: =VLOOKUP(DVF_Filtering[[#This Row],[ID]],'2. Use Cases'!A:B,2,FALSE) -> HyperPersonalization | C8: 1 | D8: 1 | E8: 1 | F8: =SUM(DVF_Filtering[[#This Row],[Desirability (1-5)]:[Feasibility (1-5)]]) -> 3 | G8: =IF(AND(C8>=3,D8>=3,E8>=3),"Pass","Fail") -> Fail
A9: UC07 | B9: =VLOOKUP(DVF_Filtering[[#This Row],[ID]],'2. Use Cases'!A:B,2,FALSE) -> Contact Centre | C9: 1 | D9: 1 | E9: 1 | F9: =SUM(DVF_Filtering[[#This Row],[Desirability (1-5)]:[Feasibility (1-5)]]) -> 3 | G9: =IF(AND(C9>=3,D9>=3,E9>=3),"Pass","Fail") -> Fail
A10: UC08 | B10: =VLOOKUP(DVF_Filtering[[#This Row],[ID]],'2. Use Cases'!A:B,2,FALSE) -> Security AI | C10: 1 | D10: 1 | E10: 1 | F10: =SUM(DVF_Filtering[[#This Row],[Desirability (1-5)]:[Feasibility (1-5)]]) -> 3 | G10: =IF(AND(C10>=3,D10>=3,E10>=3),"Pass","Fail") -> Fail
A11: UC09 | B11: =VLOOKUP(DVF_Filtering[[#This Row],[ID]],'2. Use Cases'!A:B,2,FALSE) -> Data Products | C11: 1 | D11: 1 | E11: 1 | F11: =SUM(DVF_Filtering[[#This Row],[Desirability (1-5)]:[Feasibility (1-5)]]) -> 3 | G11: =IF(AND(C11>=3,D11>=3,E11>=3),"Pass","Fail") -> Fail
A12: UC10 | B12: =VLOOKUP(DVF_Filtering[[#This Row],[ID]],'2. Use Cases'!A:B,2,FALSE) -> SDLC | C12: 1 | D12: 1 | E12: 1 | F12: =SUM(DVF_Filtering[[#This Row],[Desirability (1-5)]:[Feasibility (1-5)]]) -> 3 | G12: =IF(AND(C12>=3,D12>=3,E12>=3),"Pass","Fail") -> Fail
A13: UC11 | B13: =VLOOKUP(DVF_Filtering[[#This Row],[ID]],'2. Use Cases'!A:B,2,FALSE) -> Fincrime | C13: 1 | D13: 1 | E13: 1 | F13: =SUM(DVF_Filtering[[#This Row],[Desirability (1-5)]:[Feasibility (1-5)]]) -> 3 | G13: =IF(AND(C13>=3,D13>=3,E13>=3),"Pass","Fail") -> Fail
A14: UC12 | B14: =VLOOKUP(DVF_Filtering[[#This Row],[ID]],'2. Use Cases'!A:B,2,FALSE) -> QA/QC | C14: 1 | D14: 1 | E14: 1 | F14: =SUM(DVF_Filtering[[#This Row],[Desirability (1-5)]:[Feasibility (1-5)]]) -> 3 | G14: =IF(AND(C14>=3,D14>=3,E14>=3),"Pass","Fail") -> Fail
... A26: UC24 | B26: =VLOOKUP(DVF_Filtering[[#This Row],[ID]],'2. Use Cases'!A:B,2,FALSE) -> Front-end App Personalisation | C26: 1 | D26: 1 | E26: 1 | F26: =SUM(DVF_Filtering[[#This Row],[Desirability (1-5)]:[Feasibility (1-5)]]) -> 3 | G26: =IF(AND(C26>=3,D26>=3,E26>=3),"Pass","Fail") -> Fail

Sheet 4. WSJF Scoring
A1: INSTRUCTIONS: Use Fibonacci sizing (1,2,3,5,8,13,20). WSJF = Cost of Delay ÷ Initiative Size. Higher WSJF = Higher Priority.
A2: ID | B2: Name | C2: Business Value | D2: Time Criticality | E2: Risk Reduction / Opptunity Enable | F2: Cost of Delay | G2: Initiative Size | H2: WSJF Score | I2: WSJF Rank
A3: ='2. Use Cases'!A2 -> UC01 | B3: =VLOOKUP(DVF_Filtering[[#This Row],[ID]],'2. Use Cases'!A:B,2,FALSE) -> FrontLine - Partnership Banking | C3: =VLOOKUP('2. Use Cases'!E2,BusinessValueTable,2,FALSE) -> 5 | D3: 1 | E3: 1 | F3: =C3+D3+E3 -> 7 | G3: 1 | H3: =IF(G3>0,F3/G3,0) -> 7 | I3: =IF(H3>0,RANK(H3,H$3:H$25,0),"") -> 1
A4: ='2. Use Cases'!A3 -> UC02 | B4: =VLOOKUP(DVF_Filtering[[#This Row],[ID]],'2. Use Cases'!A:B,2,FALSE) -> Finance | C4: =VLOOKUP('2. Use Cases'!E3,BusinessValueTable,2,FALSE) -> 5 | D4: 1 | E4: 1 | F4: =C4+D4+E4 -> 7 | G4: 1 | H4: =IF(G4>0,F4/G4,0) -> 7 | I4: =IF(H4>0,RANK(H4,H$3:H$25,0),"") -> 1
A5: ='2. Use Cases'!A4 -> UC03 | B5: =VLOOKUP(DVF_Filtering[[#This Row],[ID]],'2. Use Cases'!A:B,2,FALSE) -> Analytics and Reporting | C5: =VLOOKUP('2. Use Cases'!E4,BusinessValueTable,2,FALSE) -> 5 | D5: 1 | E5: 1 | F5: =C5+D5+E5 -> 7 | G5: 1 | H5: =IF(G5>0,F5/G5,0) -> 7 | I5: =IF(H5>0,RANK(H5,H$3:H$25,0),"") -> 1
A6: ='2. Use Cases'!A5 -> UC04 | B6: =VLOOKUP(DVF_Filtering[[#This Row],[ID]],'2. Use Cases'!A:B,2,FALSE) -> Credit Risk | C6: =VLOOKUP('2. Use Cases'!E5,BusinessValueTable,2,FALSE) -> 5 | D6: 1 | E6: 1 | F6: =C6+D6+E6 -> 7 | G6: 1 | H6: =IF(G6>0,F6/G6,0) -> 7 | I6: =IF(H6>0,RANK(H6,H$3:H$25,0),"") -> 1
A7: ='2. Use Cases'!A6 -> UC05 | B7: =VLOOKUP(DVF_Filtering[[#This Row],[ID]],'2. Use Cases'!A:B,2,FALSE) -> Lending Ops | C7: =VLOOKUP('2. Use Cases'!E6,BusinessValueTable,2,FALSE) -> 5 | D7: 1 | E7: 1 | F7: =C7+D7+E7 -> 7 | G7: 1 | H7: =IF(G7>0,F7/G7,0) -> 7 | I7: =IF(H7>0,RANK(H7,H$3:H$25,0),"") -> 1
A8: ='2. Use Cases'!A7 -> UC06 | B8: =VLOOKUP(DVF_Filtering[[#This Row],[ID]],'2. Use Cases'!A:B,2,FALSE) -> HyperPersonalization | C8: =VLOOKUP('2. Use Cases'!E7,BusinessValueTable,2,FALSE) -> 5 | D8: 1 | E8: 1 | F8: =C8+D8+E8 -> 7 | G8: 1 | H8: =IF(G8>0,F8/G8,0) -> 7 | I8: =IF(H8>0,RANK(H8,H$3:H$25,0),"") -> 1
A9: ='2. Use Cases'!A8 -> UC07 | B9: =VLOOKUP(DVF_Filtering[[#This Row],[ID]],'2. Use Cases'!A:B,2,FALSE) -> Contact Centre | C9: =VLOOKUP('2. Use Cases'!E8,BusinessValueTable,2,FALSE) -> 5 | D9: 1 | E9: 1 | F9: =C9+D9+E9 -> 7 | G9: 1 | H9: =IF(G9>0,F9/G9,0) -> 7 | I9: =IF(H9>0,RANK(H9,H$3:H$25,0),"") -> 1
A10: ='2. Use Cases'!A9 -> UC08 | B10: =VLOOKUP(DVF_Filtering[[#This Row],[ID]],'2. Use Cases'!A:B,2,FALSE) -> Security AI | C10: =VLOOKUP('2. Use Cases'!E9,BusinessValueTable,2,FALSE) -> 5 | D10: 1 | E10: 1 | F10: =C10+D10+E10 -> 7 | G10: 1 | H10: =IF(G10>0,F10/G10,0) -> 7 | I10: =IF(H10>0,RANK(H10,H$3:H$25,0),"") -> 1
A11: ='2. Use Cases'!A10 -> UC09 | B11: =VLOOKUP(DVF_Filtering[[#This Row],[ID]],'2. Use Cases'!A:B,2,FALSE) -> Data Products | C11: =VLOOKUP('2. Use Cases'!E10,BusinessValueTable,2,FALSE) -> 5 | D11: 1 | E11: 1 | F11: =C11+D11+E11 -> 7 | G11: 1 | H11: =IF(G11>0,F11/G11,0) -> 7 | I11: =IF(H11>0,RANK(H11,H$3:H$25,0),"") -> 1
A12: ='2. Use Cases'!A11 -> UC10 | B12: =VLOOKUP(DVF_Filtering[[#This Row],[ID]],'2. Use Cases'!A:B,2,FALSE) -> SDLC | C12: =VLOOKUP('2. Use Cases'!E11,BusinessValueTable,2,FALSE) -> 5 | D12: 1 | E12: 1 | F12: =C12+D12+E12 -> 7 | G12: 1 | H12: =IF(G12>0,F12/G12,0) -> 7 | I12: =IF(H12>0,RANK(H12,H$3:H$25,0),"") -> 1
A13: ='2. Use Cases'!A12 -> UC11 | B13: =VLOOKUP(DVF_Filtering[[#This Row],[ID]],'2. Use Cases'!A:B,2,FALSE) -> Fincrime | C13: =VLOOKUP('2. Use Cases'!E12,BusinessValueTable,2,FALSE) -> 5 | D13: 1 | E13: 1 | F13: =C13+D13+E13 -> 7 | G13: 1 | H13: =IF(G13>0,F13/G13,0) -> 7 | I13: =IF(H13>0,RANK(H13,H$3:H$25,0),"") -> 1
A14: ='2. Use Cases'!A13 -> UC12 | B14: =VLOOKUP(DVF_Filtering[[#This Row],[ID]],'2. Use Cases'!A:B,2,FALSE) -> QA/QC | C14: =VLOOKUP('2. Use Cases'!E13,BusinessValueTable,2,FALSE) -> 5 | D14: 1 | E14: 1 | F14: =C14+D14+E14 -> 7 | G14: 1 | H14: =IF(G14>0,F14/G14,0) -> 7 | I14: =IF(H14>0,RANK(H14,H$3:H$25,0),"") -> 1
... A26: ='2. Use Cases'!A25 -> UC24 | B26: =VLOOKUP(DVF_Filtering[[#This Row],[ID]],'2. Use Cases'!A:B,2,FALSE) -> Front-end App Personalisation | C26: =VLOOKUP('2. Use Cases'!E25,BusinessValueTable,2,FALSE) -> 5 | D26: 1 | E26: 1 | F26: =C26+D26+E26 -> 7 | G26: 1 | H26: =IF(G26>0,F26/G26,0) -> 7 | I26: =IF(H26>0,RANK(H26,H$3:H$25,0),"") -> 1

Sheet 5. Dependencies Schedule
A1: INSTRUCTIONS: Document dependencies. Assign waves: Wave 1 (Q1-Q3 2026), Wave 2 (Q4 2026-Q3 2027), Wave 3 (Q4 2027-Q2 2028)
A2: ID | B2: Name | C2: WSJF Rank | D2: Prerequisites (IDs) | E2: Enables (IDs) | F2: Earliest Start | G2: Recommended Wave | H2: Rationale
A3: ='2. Use Cases'!A2 -> UC01 | B3: ='2. Use Cases'!B2 -> FrontLine - Partnership Banking | C3: ='4. WSJF Scoring'!I3 -> 1
A4: ='2. Use Cases'!A3 -> UC02 | B4: ='2. Use Cases'!B3 -> Finance | C4: ='4. WSJF Scoring'!I4 -> 1
A5: ='2. Use Cases'!A4 -> UC03 | B5: ='2. Use Cases'!B4 -> Analytics and Reporting | C5: ='4. WSJF Scoring'!I5 -> 1
A6: ='2. Use Cases'!A5 -> UC04 | B6: ='2. Use Cases'!B5 -> Credit Risk | C6: ='4. WSJF Scoring'!I6 -> 1
A7: ='2. Use Cases'!A6 -> UC05 | B7: ='2. Use Cases'!B6 -> Lending Ops | C7: ='4. WSJF Scoring'!I7 -> 1
A8: ='2. Use Cases'!A7 -> UC06 | B8: ='2. Use Cases'!B7 -> HyperPersonalization | C8: ='4. WSJF Scoring'!I8 -> 1
A9: ='2. Use Cases'!A8 -> UC07 | B9: ='2. Use Cases'!B8 -> Contact Centre | C9: ='4. WSJF Scoring'!I9 -> 1
A10: ='2. Use Cases'!A9 -> UC08 | B10: ='2. Use Cases'!B9 -> Security AI | C10: ='4. WSJF Scoring'!I10 -> 1
A11: ='2. Use Cases'!A10 -> UC09 | B11: ='2. Use Cases'!B10 -> Data Products | C11: ='4. WSJF Scoring'!I11 -> 1
A12: ='2. Use Cases'!A11 -> UC10 | B12: ='2. Use Cases'!B11 -> SDLC | C12: ='4. WSJF Scoring'!I12 -> 1
A13: ='2. Use Cases'!A12 -> UC11 | B13: ='2. Use Cases'!B12 -> Fincrime | C13: ='4. WSJF Scoring'!I13 -> 1
A14: ='2. Use Cases'!A13 -> UC12 | B14: ='2. Use Cases'!B13 -> QA/QC | C14: ='4. WSJF Scoring'!I14 -> 1
... A26: ='2. Use Cases'!A25 -> UC24 | B26: ='2. Use Cases'!B25 -> Front-end App Personalisation | C26: ='4. WSJF Scoring'!I26 -> 1

Sheet 6. Portfolio View
A1: INSTRUCTIONS: Portfolio view with automatic tier calculations. Mark Top 10 and Top 5 checkboxes. Add Notes for presentation.
A2: ID | B2: Name | C2: WSJF Rank | D2: Cost of Delay | E2: Iniative Size | F2: Value Tier | G2: Effort Tier | H2: Quadrant | I2: Wave | J2: Top 10 | K2: Top 5 | L2: Notes
A3: ='2. Use Cases'!A2 -> UC01 | B3: =VLOOKUP(DVF_Filtering[[#This Row],[ID]],'2. Use Cases'!A:B,2,FALSE) -> FrontLine - Partnership Banking | C3: ='4. WSJF Scoring'!I3 -> 1 | D3: ='4. WSJF Scoring'!F3 -> 7 | E3: ='4. WSJF Scoring'!G3 -> 1 | F3: =IF(D3>=30,"High",IF(D3>=15,"Medium","Low")) -> Low | G3: =IF(E3>=13,"High",IF(E3>=5,"Medium","Low")) -> Low | H3: =IF(F3="High",IF(G3="Low","Quick Win","Strategic Bet"),IF(F3="Medium","Fill-in","Avoid")) -> Avoid | I3: ='5. Dependencies Schedule'!G3 -> 0 | J3: No | K3: No
A4: ='2. Use Cases'!A3 -> UC02 | B4: =VLOOKUP(DVF_Filtering[[#This Row],[ID]],'2. Use Cases'!A:B,2,FALSE) -> Finance | C4: ='4. WSJF Scoring'!I4 -> 1 | D4: ='4. WSJF Scoring'!F4 -> 7 | E4: ='4. WSJF Scoring'!G4 -> 1 | F4: =IF(D4>=30,"High",IF(D4>=15,"Medium","Low")) -> Low | G4: =IF(E4>=13,"High",IF(E4>=5,"Medium","Low")) -> Low | H4: =IF(F4="High",IF(G4="Low","Quick Win","Strategic Bet"),IF(F4="Medium","Fill-in","Avoid")) -> Avoid | I4: ='5. Dependencies Schedule'!G4 -> 0 | J4: No | K4: No
A5: ='2. Use Cases'!A4 -> UC03 | B5: =VLOOKUP(DVF_Filtering[[#This Row],[ID]],'2. Use Cases'!A:B,2,FALSE) -> Analytics and Reporting | C5: ='4. WSJF Scoring'!I5 -> 1 | D5: ='4. WSJF Scoring'!F5 -> 7 | E5: ='4. WSJF Scoring'!G5 -> 1 | F5: =IF(D5>=30,"High",IF(D5>=15,"Medium","Low")) -> Low | G5: =IF(E5>=13,"High",IF(E5>=5,"Medium","Low")) -> Low | H5: =IF(F5="High",IF(G5="Low","Quick Win","Strategic Bet"),IF(F5="Medium","Fill-in","Avoid")) -> Avoid | I5: ='5. Dependencies Schedule'!G5 -> 0 | J5: No | K5: No
A6: ='2. Use Cases'!A5 -> UC04 | B6: =VLOOKUP(DVF_Filtering[[#This Row],[ID]],'2. Use Cases'!A:B,2,FALSE) -> Credit Risk | C6: ='4. WSJF Scoring'!I6 -> 1 | D6: ='4. WSJF Scoring'!F6 -> 7 | E6: ='4. WSJF Scoring'!G6 -> 1 | F6: =IF(D6>=30,"High",IF(D6>=15,"Medium","Low")) -> Low | G6: =IF(E6>=13,"High",IF(E6>=5,"Medium","Low")) -> Low | H6: =IF(F6="High",IF(G6="Low","Quick Win","Strategic Bet"),IF(F6="Medium","Fill-in","Avoid")) -> Avoid | I6: ='5. Dependencies Schedule'!G6 -> 0 | J6: No | K6: No
A7: ='2. Use Cases'!A6 -> UC05 | B7: =VLOOKUP(DVF_Filtering[[#This Row],[ID]],'2. Use Cases'!A:B,2,FALSE) -> Lending Ops | C7: ='4. WSJF Scoring'!I7 -> 1 | D7: ='4. WSJF Scoring'!F7 -> 7 | E7: ='4. WSJF Scoring'!G7 -> 1 | F7: =IF(D7>=30,"High",IF(D7>=15,"Medium","Low")) -> Low | G7: =IF(E7>=13,"High",IF(E7>=5,"Medium","Low")) -> Low | H7: =IF(F7="High",IF(G7="Low","Quick Win","Strategic Bet"),IF(F7="Medium","Fill-in","Avoid")) -> Avoid | I7: ='5. Dependencies Schedule'!G7 -> 0 | J7: No | K7: No
A8: ='2. Use Cases'!A7 -> UC06 | B8: =VLOOKUP(DVF_Filtering[[#This Row],[ID]],'2. Use Cases'!A:B,2,FALSE) -> HyperPersonalization | C8: ='4. WSJF Scoring'!I8 -> 1 | D8: ='4. WSJF Scoring'!F8 -> 7 | E8: ='4. WSJF Scoring'!G8 -> 1 | F8: =IF(D8>=30,"High",IF(D8>=15,"Medium","Low")) -> Low | G8: =IF(E8>=13,"High",IF(E8>=5,"Medium","Low")) -> Low | H8: =IF(F8="High",IF(G8="Low","Quick Win","Strategic Bet"),IF(F8="Medium","Fill-in","Avoid")) -> Avoid | I8: ='5. Dependencies Schedule'!G8 -> 0 | J8: No | K8: No
A9: ='2. Use Cases'!A8 -> UC07 | B9: =VLOOKUP(DVF_Filtering[[#This Row],[ID]],'2. Use Cases'!A:B,2,FALSE) -> Contact Centre | C9: ='4. WSJF Scoring'!I9 -> 1 | D9: ='4. WSJF Scoring'!F9 -> 7 | E9: ='4. WSJF Scoring'!G9 -> 1 | F9: =IF(D9>=30,"High",IF(D9>=15,"Medium","Low")) -> Low | G9: =IF(E9>=13,"High",IF(E9>=5,"Medium","Low")) -> Low | H9: =IF(F9="High",IF(G9="Low","Quick Win","Strategic Bet"),IF(F9="Medium","Fill-in","Avoid")) -> Avoid | I9: ='5. Dependencies Schedule'!G9 -> 0 | J9: No | K9: No
A10: ='2. Use Cases'!A9 -> UC08 | B10: =VLOOKUP(DVF_Filtering[[#This Row],[ID]],'2. Use Cases'!A:B,2,FALSE) -> Security AI | C10: ='4. WSJF Scoring'!I10 -> 1 | D10: ='4. WSJF Scoring'!F10 -> 7 | E10: ='4. WSJF Scoring'!G10 -> 1 | F10: =IF(D10>=30,"High",IF(D10>=15,"Medium","Low")) -> Low | G10: =IF(E10>=13,"High",IF(E10>=5,"Medium","Low")) -> Low | H10: =IF(F10="High",IF(G10="Low","Quick Win","Strategic Bet"),IF(F10="Medium","Fill-in","Avoid")) -> Avoid | I10: ='5. Dependencies Schedule'!G10 -> 0 | J10: No | K10: No
A11: ='2. Use Cases'!A10 -> UC09 | B11: =VLOOKUP(DVF_Filtering[[#This Row],[ID]],'2. Use Cases'!A:B,2,FALSE) -> Data Products | C11: ='4. WSJF Scoring'!I11 -> 1 | D11: ='4. WSJF Scoring'!F11 -> 7 | E11: ='4. WSJF Scoring'!G11 -> 1 | F11: =IF(D11>=30,"High",IF(D11>=15,"Medium","Low")) -> Low | G11: =IF(E11>=13,"High",IF(E11>=5,"Medium","Low")) -> Low | H11: =IF(F11="High",IF(G11="Low","Quick Win","Strategic Bet"),IF(F11="Medium","Fill-in","Avoid")) -> Avoid | I11: ='5. Dependencies Schedule'!G11 -> 0 | J11: No | K11: No
A12: ='2. Use Cases'!A11 -> UC10 | B12: =VLOOKUP(DVF_Filtering[[#This Row],[ID]],'2. Use Cases'!A:B,2,FALSE) -> SDLC | C12: ='4. WSJF Scoring'!I12 -> 1 | D12: ='4. WSJF Scoring'!F12 -> 7 | E12: ='4. WSJF Scoring'!G12 -> 1 | F12: =IF(D12>=30,"High",IF(D12>=15,"Medium","Low")) -> Low | G12: =IF(E12>=13,"High",IF(E12>=5,"Medium","Low")) -> Low | H12: =IF(F12="High",IF(G12="Low","Quick Win","Strategic Bet"),IF(F12="Medium","Fill-in","Avoid")) -> Avoid | I12: ='5. Dependencies Schedule'!G12 -> 0 | J12: No | K12: No
A13: ='2. Use Cases'!A12 -> UC11 | B13: =VLOOKUP(DVF_Filtering[[#This Row],[ID]],'2. Use Cases'!A:B,2,FALSE) -> Fincrime | C13: ='4. WSJF Scoring'!I13 -> 1 | D13: ='4. WSJF Scoring'!F13 -> 7 | E13: ='4. WSJF Scoring'!G13 -> 1 | F13: =IF(D13>=30,"High",IF(D13>=15,"Medium","Low")) -> Low | G13: =IF(E13>=13,"High",IF(E13>=5,"Medium","Low")) -> Low | H13: =IF(F13="High",IF(G13="Low","Quick Win","Strategic Bet"),IF(F13="Medium","Fill-in","Avoid")) -> Avoid | I13: ='5. Dependencies Schedule'!G13 -> 0 | J13: No | K13: No
A14: ='2. Use Cases'!A13 -> UC12 | B14: =VLOOKUP(DVF_Filtering[[#This Row],[ID]],'2. Use Cases'!A:B,2,FALSE) -> QA/QC | C14: ='4. WSJF Scoring'!I14 -> 1 | D14: ='4. WSJF Scoring'!F14 -> 7 | E14: ='4. WSJF Scoring'!G14 -> 1 | F14: =IF(D14>=30,"High",IF(D14>=15,"Medium","Low")) -> Low | G14: =IF(E14>=13,"High",IF(E14>=5,"Medium","Low")) -> Low | H14: =IF(F14="High",IF(G14="Low","Quick Win","Strategic Bet"),IF(F14="Medium","Fill-in","Avoid")) -> Avoid | I14: ='5. Dependencies Schedule'!G14 -> 0 | J14: No | K14: No
... A26: ='2. Use Cases'!A25 -> UC24 | B26: =VLOOKUP(DVF_Filtering[[#This Row],[ID]],'2. Use Cases'!A:B,2,FALSE) -> Front-end App Personalisation | C26: ='4. WSJF Scoring'!I26 -> 1 | D26: ='4. WSJF Scoring'!F26 -> 7 | E26: ='4. WSJF Scoring'!G26 -> 1 | F26: =IF(D26>=30,"High",IF(D26>=15,"Medium","Low")) -> Low | G26: =IF(E26>=13,"High",IF(E26>=5,"Medium","Low")) -> Low | H26: =IF(F26="High",IF(G26="Low","Quick Win","Strategic Bet"),IF(F26="Medium","Fill-in","Avoid")) -> Avoid | I26: ='5. Dependencies Schedule'!G26 -> 0 | J26: No | K26: No

Sheet 7. Solutions
A1: ID | B1: Name | C1: AI Type | D1: Category | E1: Strategic Theme
A2: UC01 | B2: =VLOOKUP(A2,'2. Use Cases'!A:B,2,FALSE) -> FrontLine - Partnership Banking | C2: Embedded/Vendor AI | D2: Customer & Relationship Management | E2: Customer Experience
A3: UC02 | B3: =VLOOKUP(A3,'2. Use Cases'!A:B,2,FALSE) -> Finance | C3: Generative AI | D3: Finance & Accounting | E3: Operational Efficiency
A4: UC03 | B4: =VLOOKUP(A4,'2. Use Cases'!A:B,2,FALSE) -> Analytics and Reporting | C4: Generative AI | D4: Data & Analytics | E4: Data-Driven Decisions
A5: UC04 | B5: =VLOOKUP(A5,'2. Use Cases'!A:B,2,FALSE) -> Credit Risk | C5: ML/AI | D5: Risk Management | E5: Risk & Compliance
A6: UC05 | B6: =VLOOKUP(A6,'2. Use Cases'!A:B,2,FALSE) -> Lending Ops | C6: Document AI | D6: Lending & Credit Operations | E6: Operational Efficiency
A7: UC06 | B7: =VLOOKUP(A7,'2. Use Cases'!A:B,2,FALSE) -> HyperPersonalization | C7: Generative AI | D7: Marketing & Personalization | E7: Customer Experience
A8: UC07 | B8: =VLOOKUP(A8,'2. Use Cases'!A:B,2,FALSE) -> Contact Centre | C8: Embedded/Vendor AI | D8: Customer Service & Support | E8: Customer Experience
A9: UC08 | B9: =VLOOKUP(A9,'2. Use Cases'!A:B,2,FALSE) -> Security AI | C9: ML/AI | D9: Cybersecurity & Threat Detection | E9: Risk & Compliance
A10: UC09 | B10: =VLOOKUP(A10,'2. Use Cases'!A:B,2,FALSE) -> Data Products | C10: Generative AI | D10: Data & Analytics | E10: Data-Driven Decisions
A11: UC10 | B11: =VLOOKUP(A11,'2. Use Cases'!A:B,2,FALSE) -> SDLC | C11: Code AI | D11: Software Development & Engineering | E11: Operational Efficiency
A12: UC11 | B12: =VLOOKUP(A12,'2. Use Cases'!A:B,2,FALSE) -> Fincrime | C12: ML/AI | D12: Compliance & Financial Crime | E12: Risk & Compliance
A13: UC12 | B13: =VLOOKUP(A13,'2. Use Cases'!A:B,2,FALSE) -> QA/QC | C13: ML/AI | D13: Quality Assurance & Compliance | E13: Operational Efficiency
... A25: UC24 | B25: =VLOOKUP(A25,'2. Use Cases'!A:B,2,FALSE) -> Front-end App Personalisation | C25: Generative AI | D25: Marketing & Personalization | E25: Customer Experience

Sheet 8. Scoring Guidelines
A1: SCORING GUIDELINES (WSJF)
A3: Aspect | B3: TERM | C3: SCORE | D3: DESCRIPTION | E3: EXAMPLES
A5: Business Value | B5: Major | C5: 20 | D5: >$5M annual benefit OR >20% efficiency gain | E5: Major revenue driver, critical customer experience
B6: Very Significant | C6: 13 | D6: $2-5M benefit OR 10-20% efficiency | E6: Significant cost savings, important customer feature
B7: Significant | C7: 8 | D7: $500K-2M benefit OR 5-10% efficiency | E7: Meaningful operational improvement
B8: Moderate | C8: 5 | D8: $100K-500K benefit OR 2-5% efficiency | E8: Moderate business value
B9: Minor | C9: 3 | D9: $50K-100K benefit OR 1-2% efficiency | E9: Small but tangible benefit
B10: Minimal | C10: 2 | D10: <$50K benefit OR <1% efficiency | E10: Minimal quantified benefit
B11: Negligible | C11: 1 | D11: Negligible benefit | E11: No clear business value
A13: Time Criticality | B13: Major < 6 months | C13: 20 | D13: Fixed regulatory deadline <6 months OR major competitive threat | E13: Compliance deadline with penalties
B14: Very Significant < 12 months | C14: 13 | D14: Fixed deadline <12 months OR significant competitive pressure | E14: Market window closing
B15: Significant < 12 months | C15: 8 | D15: Preferred timing <12 months OR moderate competitive benefit | E15: Seasonal opportunity
B16: Moderate < 18 months | C16: 5 | D16: Beneficial timing <18 months | E16: Loose timing preference
B17: Minor < 24 months | C17: 3 | D17: Timing preference <24 months | E17: Minor timing consideration
B18: Minimal | C18: 2 | D18: No specific timing driver | E18: Flexible timing
B19: Negligible | C19: 1 | D19: Can be done anytime | E19: No urgency
A21: Risk Reduction / Opportunity Enablement | B21: Major | C21: 20 | D21: Eliminates critical risk OR enables 5+ use cases | E21: Major security vulnerability, platform foundation
B22: Very Significant | C22: 13 | D22: Significantly reduces high risk OR enables 3-4 use cases | E22: Compliance risk, key infrastructure
B23: Significant | C23: 8 | D23: Reduces moderate risk OR enables 2 use cases | E23: Technical debt, reusable component
B24: Moderate | C24: 5 | D24: Reduces minor risk OR enables 1 use case | E24: Small risk mitigation
B25: Minor | C25: 3 | D25: Small risk reduction OR creates reusable component | E25: Incremental improvement
B26: Minimal | C26: 2 | D26: Minimal risk impact | E26: Negligible risk reduction
B27: Negligible | C27: 1 | D27: No risk reduction or enabling capability | E27: No strategic value
A29: Initiative Size | B29: Major | C29: 20 | D29: 18+ months OR >100 person-months | E29: Enterprise transformation
B30: Very Significant | C30: 13 | D30: 12-18 months OR 50-100 person-months | E30: Major program
B31: Significant | C31: 8 | D31: 6-12 months OR 20-50 person-months | E31: Significant project
B32: Moderate | C32: 5 | D32: 3-6 months OR 10-20 person-months | E32: Standard project
B33: Minor | C33: 3 | D33: 1-3 months OR 5-10 person-months | E33: Small project
B34: Minimal | C34: 2 | D34: <1 month OR <5 person-months | E34: Very small initiative
B35: Trivial | C35: 1 | D35: Minimal effort | E35: Trivial change
A40: SCORING GUIDELINES (DVF )
A42: DIMENSION | B42: TERM | C42: SCORE | D42: DESCRIPTION | E42: KEY QUESTIONS
A44: Desirability | B44: Excellent | C44: 5 | D44: Strong evidence colleagues or customers want this. | E44: Does it solve a critical pain point? Is demand validated?
B45: Good | C45: 4 | D45: Clear colleague or customer demand. | E45: Is there user research supporting this?
B46: Acceptable | C46: 3 | D46: Meets minimum colleague or customer needs. | E46: Do users see value in this?
B47: Poor | C47: 2 | D47: Unclear if colleagues or customers want this. | E47: Is this an assumption or validated need?
B48: Very Poor | C48: 1 | D48: Colleagues or customers unlikely to adopt. | E48: Are we solving the wrong problem?
A50: Viability | B50: Excellent | C50: 5 | D50: Strong financial case, strategic alignment. | E50: Does it align with strategy? Is ROI clear?
B51: Good | C51: 4 | D51: Clear business case. | E51: Can we afford it? Does it fit our model?
B52: Acceptable | C52: 3 | D52: Financially viable. | E52: Is the business case sound?
...
