Workbook

Sheet Summary
A1: Cost Category | B1: Monthly Cost (USD) | C1: Percentage | D1: Notes
A2: AgentCore Services | B2: =Calculations!B2 -> #VALUE! | C2: =B1/$B$10*100 -> #VALUE! | D2: Runtime, Browser, Code Interpreter, Gateway, Observability
A3: Foundation Models (Bedrock) | B3: =Calculations!B3 -> #REF! | C3: =B2/$B$10*100 -> #VALUE! | D3: Claude 3.5, Haiku, Llama models
A4: Supporting AWS Services | B4: =Calculations!B4 -> #REF! | C4: =B3/$B$10*100 -> #REF! | D4: EC2, Lambda, S3, DynamoDB
A5: Data Transfer & Storage | B5: =Calculations!B5 -> #REF! | C5: =B4/$B$10*100 -> #REF! | D5: Inter-AZ, Internet egress, S3 storage
A6: Monitoring & Logging | B6: =Calculations!B6 -> #REF! | C6: =B5/$B$10*100 -> #REF! | D6: CloudWatch metrics, logs, dashboards
A7: Network Infrastructure | B7: =Calculations!B7 -> #REF! | C7: =B6/$B$10*100 -> #REF! | D7: VPC, NAT Gateway, Load Balancer
A8: Security & Compliance | B8: =Calculations!B8 -> #REF! | C8: =B7/$B$10*100 -> #REF! | D8: KMS, IAM, SSL certificates
A9: Vector Database Services | B9: =Calculations!B9 -> #REF! | C9: =B8/$B$10*100 -> #REF! | D9: S3 Vectors, OpenSearch, Pinecone vector search
A10: Graph Database Services | B10: =Calculations!B10 -> #REF! | C10: =B9/$B$10*100 -> #REF! | D10: Neptune, Neo4j knowledge graphs, GraphRAG
A11: TOTAL MONTHLY COST | B11: =SUM(B1:B9) -> #VALUE! | C11: 100% | D11: Total estimated monthly cost

Sheet Assumptions
A1: Category | B1: Value | C1: Unit | D1: Description
A2: PROJECT ASSUMPTIONS
A3: Team Size | B3: 10 | C3: People | D3: Number of sandbox users in community
A4: Active Hours per Day | B4: 8 | C4: Hours | D4: Daily active usage hours
A5: Working Days per Month | B5: 22 | C5: Days | D5: Business days per month
A6: Sessions per User per Day | B6: 3 | C6: Sessions | D6: AgentCore sessions per user daily
A7: Average Session Duration | B7: 120 | C7: Seconds | D7: Typical session length
A8: Peak Concurrent Users | B8: 5 | C8: Users | D8: Maximum simultaneous users
A9: Data Storage Growth | B9: 10 | C9: GB/Month | D9: Monthly data accumulation
A10: MODEL USAGE DISTRIBUTION
A11: Claude Sonnet 4 | B11: 40 | C11: % | D11: Percentage of model usage
A12: Claude 3.5 Haiku | B12: 30 | C12: % | D12: Percentage of model usage
A13: Llama 3.1 70B | B13: 20 | C13: % | D13: Percentage of model usage
A14: Llama 3.1 8B | B14: 10 | C14: % | D14: Percentage of model usage
A15: Average Input Tokens per Session | B15: 500 | C15: Tokens | D15: Typical prompt size
A16: Average Output Tokens per Session | B16: 300 | C16: Tokens | D16: Typical response size
A17: VECTOR DATABASE ASSUMPTIONS
A18: Vector Dimensions | B18: 1536 | C18: Dimensions | D18: Vector embedding dimensions
A19: Vectors per User | B19: 1000 | C19: Vectors | D19: Number of vectors per user
A20: Vector Storage Growth | B20: 20 | C20: Percent Growth/Month | D20: Monthly vector storage growth
A21: Vector Queries per Session | B21: 2 | C21: Queries | D21: Vector searches per session
A22: Vector Search Precision | B22: 95% | C22: Accuracy | D22: Target search accuracy
A23: Embedding Model | B23: text-embedding-ada-002 | C23: Model | D23: Embedding model for vectors
A24: GRAPH DATABASE ASSUMPTIONS
A25: Entities per User | B25: 50 | C25: Entities | D25: Knowledge graph entities per user
A26: Relationships per Entity | B26: 3 | C26: Relationships | D26: Average relationships per entity
A27: Graph Queries per Session | B27: 1 | C27: Queries | D27: Graph queries per session
A28: Knowledge Graph Depth | B28: 4 | C28: Levels | D28: Knowledge graph traversal depth
A29: GraphRAG Integration | B29: Enabled | C29: Boolean | D29: GraphRAG integration enabled
A30: Graph ML Training Frequency | B30: Weekly | C30: Frequency | D30: Graph ML model training frequency
A31: TECHNICAL SPECIFICATIONS
A32: CPU Usage per Session | B32: 0.5 | C32: vCPU | D32: Processing requirement
A33: Memory Usage per Session | B33: 1 | C33: GB | D33: RAM requirement
A34: Storage per User | B34: 5 | C34: GB | D34: Individual storage allocation
A35: Log Retention Period | B35: 30 | C35: Days | D35: CloudWatch log retention
A36: AWS Region | B36: us-east-1 | C36: Region | D36: Primary deployment region
A37: Availability Zones | B37: 2 | C37: Count | D37: Multi-AZ deployment
A38: VPC CIDR | B38: 10.0.0.0/16 | C38: CIDR | D38: Network address space
A39: Environment Type | B39: Sandbox | C39: Type | D39: Development / learning environment

Sheet AWS Pricing
A1: Category | B1: Component | C1: Resource | D1: Type | E1: Variant | F1: Pricing Unit | G1: Region | H1: Price (USD) | I1: Last Updated | J1: Notes
A2: AgentCore Services | B2: Runtime | C2: CPU | D2: Consumption based | E2: Default | F2: vCPU-hour | G2: us-east-1 | H2: 0.0895
A3: AgentCore Services | B3: Runtime | C3: Memory | D3: Consumption based | E3: Default | F3: GB-hour | G3: us-east-1 | H3: 0.00945
A4: AgentCore Services | B4: Browser Tool | C4: CPU | D4: Consumption Based | E4: Default | F4: vCPU-hour | G4: us-east-1 | H4: 0.0895
A5: AgentCore Services | B5: Browser Tool | C5: Memory | D5: Consumption Based | E5: Default | F5: GB-hour | G5: us-east-1 | H5: 0.00945
A6: AgentCore Services | B6: Code Interpreter | C6: CPU | D6: Consumption Based | E6: Default | F6: vCPU-hour | G6: us-east-1 | H6: 0.0895
A7: AgentCore Services | B7: Code Interpreter | C7: Memory | D7: Consumption Based | E7: Default | F7: GB-hour | G7: us-east-1 | H7: 0.00945
A8: AgentCore Services | B8: Gateway | C8: API Invocations (ListTools, InvokeTool, Ping) | D8: Consumption Based | E8: Default | F8: 1,000 invocations | G8: us-east-1 | H8: 0.005
A9: AgentCore Services | B9: Gateway | C9: Search API | D9: Consumption Based | E9: Default | F9: 1,000 invocations | G9: us-east-1 | H9: 0.025
A10: AgentCore Services | B10: Gateway | C10: Tool Indexing | D10: Consumption Based | E10: Default | F10: 100 tools indexed per month | G10: us-east-1 | H10: 0.02
A11: AgentCore Services | B11: Identity | C11: Token or API key requests for non-AWS resources | D11: Consumption Based | E11: Default | F11: 1,000 token or API keys requested by the agent | G11: us-east-1 | H11: 0.01 | J11: AgentCore Identity is available at no additional charge to customers when they use it through either AgentCore Runtime or AgentCore Gateway.
A12: AgentCore Services | B12: Memory | C12: Short-Term Memory | D12: Consumption Based | E12: Default | F12: 1,000 new events | G12: us-east-1 | H12: 0.25
A13: AgentCore Services | B13: Memory | C13: Long-Term Memory Storage | D13: Consumption Based | E13: Using built-in memory strategies | F13: 1000 memory records stored per month | G13: us-east-1 | H13: 0.75
A14: AgentCore Services | B14: Memory | C14: Long-Term Memory Storage | D14: Consumption Based | E14: Using built-in with override or self-managed memory strategies | F14: 1000 memory records stored per month. | G14: us-east-1 | H14: 0.25 | J14: For built-in with override and self-managed strategies, you may incur additional charges for the model usage in your account.
A15: AgentCore Services | B15: Memory | C15: Long-Term Memory Retrieval | D15: Consumption Based | E15: Default | F15: 1000 memory record retrievals | G15: us-east-1 | H15: 0.5
A16: AgentCore Services | B16: AgentCore Observability | C16: Data Ingestion | F16: per GB | G16: us-east-1 | H16: 0.5 | J16: CloudWatch Logs ingestion
A17: AgentCore Services | B17: AgentCore Observability | C17: Data Storage | F17: per GB-month | G17: us-east-1 | H17: 0.03 | J17: CloudWatch Logs storage
A18: AgentCore Services | B18: AgentCore Observability | C18: Queries | F18: per 1000 queries | G18: us-east-1 | H18: 0.005 | J18: Log analysis queries
A19: Foundation Models | B19: Bedrock Claude Sonnet 4 | C19: Input Tokens | F19: per 1K tokens | G19: us-east-1 | H19: 0.003 | J19: Text generation input
A20: Foundation Models | B20: Bedrock Claude Sonnet 4 | C20: Output Tokens | F20: per 1K tokens | G20: us-east-1 | H20: 0.015 | J20: Text generation output
A21: Foundation Models | B21: Bedrock Claude 3.5 Haiku | C21: Input Tokens | F21: per 1K tokens | G21: us-east-1 | H21: 0.00025 | J21: Lightweight model
A22: Foundation Models | B22: Bedrock Claude 3.5 Haiku | C22: Output Tokens | F22: per 1K tokens | G22: us-east-1 | H22: 0.00125 | J22: Lightweight model
A23: Foundation Models | B23: Bedrock Claude Opus 4 | C23: Input Tokens | F23: per 1K tokens | G23: us-east-1 | H23: 0.015 | J23: Most capable model
A24: Foundation Models | B24: Bedrock Claude Opus 4 | C24: Output Tokens | F24: per 1K tokens | G24: us-east-1 | H24: 0.075 | J24: Most capable model
A25: Compute | B25: EC2 t3.micro | C25: Instance Hour | F25: per hour | G25: us-east-1 | H25: 0.0104 | J25: Burstable performance
A26: Compute | B26: EC2 t3.small | C26: Instance Hour | F26: per hour | G26: us-east-1 | H26: 0.0208 | J26: Burstable performance
A27: Compute | B27: EC2 t3.medium | C27: Instance Hour | F27: per hour | G27: us-east-1 | H27: 0.0416 | J27: Burstable performance
... A36: Storage | B36: S3 PUT Requests | C36: Requests | F36: per 1K requests | G36: us-east-1 | H36: 0.005 | J36: Data upload
B37: DynamoDB On-Demand RRU | C37: Read Request Units | F37: per 1M RRUs | G37: us-east-1 | H37: 0.25 | J37: Pay per request
B38: DynamoDB On-Demand WRU | C38: Write Request Units | F38: per 1M WRUs | G38: us-east-1 | H38: 1.25 | J38: Pay per request
B39: DynamoDB Storage | C39: Storage | F39: per GB-month | G39: us-east-1 | H39: 0.25 | J39: Data storage
A40: Observability | B40: CloudWatch Custom Metrics | C40: Metrics | F40: per metric-month | G40: us-east-1 | H40: 0.3 | J40: First 10K free
A41: Observability | B41: CloudWatch Log Ingestion | C41: Data Ingestion | F41: per GB | G41: us-east-1 | H41: 0.5 | J41: First 5GB free monthly
A42: Observability | B42: CloudWatch Log Storage | C42: Data Storage | F42: per GB-month | G42: us-east-1 | H42: 0.03 | J42: Compressed storage
A43: Networking | B43: VPC NAT Gateway Hours | C43: Instance Hours | F43: per hour | G43: us-east-1 | H43: 0.045 | J43: Highly available NAT
A44: Networking | B44: VPC NAT Gateway Data | C44: Data Processing | F44: per GB | G44: us-east-1 | H44: 0.045 | J44: Data processed
A45: Networking | B45: Data Transfer Inter-AZ | C45: Data Transfer | F45: per GB | G45: us-east-1 | H45: 0.01 | J45: Between AZs same region
A46: Networking | B46: Data Transfer Internet 1GB-10TB | C46: Data Transfer | F46: per GB | G46: us-east-1 | H46: 0.09 | J46: Next 9.999TB
A47: Storage | B47: S3 Vectors Storage | C47: Vector Storage | F47: per GB-month | G47: us-east-1 | H47: 0.012 | J47: Vector storage in S3
A48: Storage | B48: S3 Vectors Query | C48: Vector Queries | F48: per 1K queries | G48: us-east-1 | H48: 0.01 | J48: Vector search operations
...

Sheet Bill of Materials
A1: Service Category | B1: Component | C1: Quantity | D1: Unit | E1: Monthly Usage | F1: Unit Cost (USD) | G1: Monthly Cost (USD)
A2: AgentCore Services | B2: AgentCore Runtime | C2: =Assumptions!#REF!*Assumptions!B3*Assumptions!B4*Assumptions!B5 -> #REF! | D2: Sessions / Month | E2: =C1 -> Quantity | F2: =('[2]AWS Pricing'!E1*Assumptions!B26+'[2]AWS Pricing'!E2*Assumptions!B27)*Assumptions!B6 -> #VALUE! | G2: =D1*E1 -> #VALUE!
A3: AgentCore Services | B3: AgentCore Browser | C3: =B1*0.3 -> #VALUE! | D3: Sessions / Month | E3: =C2 -> #REF! | F3: =('[2]AWS Pricing'!E3*Assumptions!B26+'[2]AWS Pricing'!E4*Assumptions!B27)*Assumptions!B6 -> #VALUE! | G3: =D2*E2 -> #VALUE!
A4: AgentCore Services | B4: AgentCore Code Interpreter | C4: =B1*0.2 -> #VALUE! | D4: Sessions / Month | E4: =C3 -> #VALUE! | F4: =('[2]AWS Pricing'!E5*Assumptions!B26+'[2]AWS Pricing'!E6*Assumptions!B27)*Assumptions!B6 -> #VALUE! | G4: =D3*E3 -> #VALUE!
A5: AgentCore Services | B5: AgentCore Gateway | C5: =B1*100 -> #VALUE! | D5: Operations / Month | E5: =C4 -> #VALUE! | F5: ='AWS Pricing'!#REF! -> #REF! | G5: =D4*E4 -> #VALUE!
A6: Foundation Models | B6: Claude 3.5 Sonnet | C6: =Assumptions!#REF!/100 -> #REF! | D6: Usage % | E6: =C5 -> #VALUE! | F6: =('[2]AWS Pricing'!E13*Assumptions!B14+'[2]AWS Pricing'!E14*Assumptions!B15)*C1/1000 -> #VALUE! | G6: =D5*E5 -> #VALUE!
A7: Foundation Models | B7: Claude 3.5 Haiku | C7: =Assumptions!B11/100 -> 0.4 | D7: Usage % | E7: =C6 -> #REF! | F7: =('[2]AWS Pricing'!E15*Assumptions!B14+'[2]AWS Pricing'!E16*Assumptions!B15)*C1/1000 -> #VALUE! | G7: =D6*E6 -> #VALUE!
A8: Foundation Models | B8: Llama 3.1 70B | C8: =Assumptions!B12/100 -> 0.3 | D8: Usage % | E8: =C7 -> 0.4 | F8: =('[2]AWS Pricing'!E19*Assumptions!B14+'[2]AWS Pricing'!E20*Assumptions!B15)*C1/1000 -> #VALUE! | G8: =D7*E7 -> #VALUE!
A9: Foundation Models | B9: Llama 3.1 8B | C9: =Assumptions!B13/100 -> 0.2 | D9: Usage % | E9: =C8 -> 0.3 | F9: =('[2]AWS Pricing'!E21*Assumptions!B14+'[2]AWS Pricing'!E22*Assumptions!B15)*C1/1000 -> #VALUE! | G9: =D8*E8 -> #VALUE!
A10: Compute Services | B10: EC2 t3.medium | C10: 2 | D10: Instances | E10: =C9*24*Assumptions!B4 -> 38.4 | F10: AWS_Pricing!E25 | G10: =D9*E9 -> #VALUE!
A11: Compute Services | B11: Lambda Functions | C11: =B1 -> Component | D11: Invocations/Month | E11: =C10 -> 2 | F11: AWS_Pricing!E30*1 | G11: =D10*E10 -> #VALUE!
A12: Compute Services | B12: Lambda ARM Functions | C12: =B1*0.5 -> #VALUE! | D12: Invocations/Month | E12: =C11 -> Component | F12: AWS_Pricing!E31*1 | G12: =D11*E11 -> #VALUE!
A13: Storage Services | B13: S3 Standard Storage | C13: =Assumptions!B8*Assumptions!#REF! -> #REF! | D13: GB | E13: =C12 -> #VALUE! | F13: AWS_Pricing!E32 | G13: =D12*E12 -> #VALUE!
A14: Storage Services | B14: S3 API Operations | C14: =B1*1000 -> #VALUE! | D14: API Calls/Month | E14: =C13 -> #REF! | F14: AWS_Pricing!E34 | G14: =D13*E13 -> #VALUE!
A15: Database Services | B15: DynamoDB Tables | C15: 3 | D15: Tables | E15: =C14 -> #VALUE! | F15: AWS_Pricing!E38 | G15: =D14*E14 -> #VALUE!
A16: Database Services | B16: DynamoDB Read Units | C16: =B1*10000 -> #VALUE! | D16: RRUs/Month | E16: =C15 -> 3 | F16: AWS_Pricing!E36 | G16: =D15*E15/1000000 -> #VALUE!
A17: Database Services | B17: DynamoDB Write Units | C17: =B1*1000 -> #VALUE! | D17: WRUs/Month | E17: =C16 -> #VALUE! | F17: AWS_Pricing!E37 | G17: =D16*E16/1000000 -> #VALUE!
A18: Monitoring Services | B18: CloudWatch Metrics | C18: =Assumptions!#REF!*5 -> #REF! | D18: Metrics | E18: =C17 -> #VALUE! | F18: AWS_Pricing!E39 | G18: =D17*E17 -> #VALUE!
A19: Monitoring Services | B19: CloudWatch Logs | C19: =B1*0.1 -> #VALUE! | D19: GB/Month | E19: =C18 -> #REF! | F19: AWS_Pricing!E40 | G19: =D18*E18 -> #VALUE!
A20: Network Services | B20: VPC NAT Gateway | C20: 1 | D20: Hours/Month | E20: =C19*24*Assumptions!B4 -> #VALUE! | F20: AWS_Pricing!E43 | G20: =D19*E19 -> #VALUE!
A21: Network Services | B21: Data Transfer | C21: =B1*0.001 -> #VALUE! | D21: GB/Month | E21: =C20 -> 1 | F21: AWS_Pricing!E46 | G21: =D20*E20 -> #VALUE!
A22: Security Services | B22: KMS Keys | C22: 2 | D22: Keys | E22: =C21 -> #VALUE! | F22: 50 | G22: =D21*E21 -> #VALUE!
A23: Vector Database Services | B23: S3 Vectors Storage | C23: =Assumptions!#REF!*Assumptions!#REF!/1000 -> #REF! | D23: GB | E23: =C22 -> 2 | F23: AWS_Pricing!E49 | G23: =D22*E22 -> #VALUE!
A24: Vector Database Services | B24: OpenSearch Serverless | C24: =C22*24*22 -> 1056 | D24: Search OCU Hours/Month | E24: =C23 -> #REF! | F24: AWS_Pricing!E51 | G24: =D23*E23 -> #VALUE!
A25: Vector Database Services | B25: Pinecone Vector DB | C25: 0.5 | D25: Pods | E25: =C24 -> 1056 | F25: AWS_Pricing!E54 | G25: =D24*E24 -> #VALUE!
A26: Graph Database Services | B26: Neptune Serverless | C26: =C24*24*22 -> 557568 | D26: NCU Hours/Month | E26: =C25 -> 0.5 | F26: AWS_Pricing!E55 | G26: =D25*E25 -> #VALUE!
A27: Graph Database Services | B27: Neo4j on EC2 | C27: 1 | D27: Instance Hours/Month | E27: =C26*24*Assumptions!B4 -> 107053056 | F27: AWS_Pricing!E58 | G27: =D26*E26 -> #VALUE!

Sheet Calculations
A1: Cost Category | B1: Formula / Value | C1: Result (USD) | D1: Notes
A2: AgentCore Services Total | B2: =SUM('Bill of Materials'!F2:F5) -> #VALUE! | D2: Runtime, Browser, Code Interpreter, Gateway costs
A3: Foundation Models Total | B3: =SUM([1]BOM!F5:F8) -> #REF! | D3: All Bedrock model inference costs
A4: Supporting AWS Services Total | B4: =SUM([1]BOM!F9:F13) -> #REF! | D4: EC2, Lambda, S3 costs
A5: Data Transfer & Storage Total | B5: =SUM([1]BOM!F12:F13,[1]BOM!F20) -> #REF! | D5: Storage and data transfer costs
A6: Monitoring & Logging Total | B6: =SUM([1]BOM!F17:F18) -> #REF! | D6: CloudWatch metrics and logs
A7: Network Infrastructure Total | B7: =SUM([1]BOM!F19:F20) -> #REF! | D7: VPC and NAT Gateway costs
A8: Security & Compliance Total | B8: =SUM([1]BOM!F21) -> #REF! | D8: KMS keys and security
A9: Vector Database Services Total | B9: =SUM([1]BOM!F22:F24) -> #REF! | D9: S3 Vectors, OpenSearch, Pinecone costs
A10: Graph Database Services Total | B10: =SUM([1]BOM!F25:F26) -> #REF! | D10: Neptune, Neo4j, and graph ML costs
A11: TOTAL MONTHLY COST | B11: =B1+B2+B3+B4+B5+B6+B7+B8+B9 -> #VALUE! | D11: Complete monthly cost estimate
A13: BREAKDOWN BY USAGE PATTERN | D13: Cost distribution by usage pattern
A15: Peak Hours Cost (70%) | B15: =B10*0.7 -> #REF! | D15: Business hours (9-5) usage cost
A16: Off-Peak Hours Cost (20%) | B16: =B10*0.2 -> #REF! | D16: After hours usage cost
A17: Weekend Cost (10%) | B17: =B10*0.1 -> #REF! | D17: Weekend usage cost
A19: COST PER USER | D19: Per-user cost metrics
A21: Monthly Cost per User | B21: =B10/Assumptions!#REF! -> #REF! | D21: Total cost divided by team size
A22: Daily Cost per User | B22: =B19/Assumptions!B4 -> 0 | D22: Monthly cost per working day
A23: Cost per Session | B23: =B19/(Assumptions!#REF!*Assumptions!B4*Assumptions!B5) -> #REF! | D23: Cost per individual session
A25: QUARTERLY PROJECTIONS | D25: Growth projections
A27: Q1 Estimate | B27: =B10*3 -> #REF! | D27: Current quarter estimate
A28: Q2 Estimate (15% growth) | B28: =B25*1.15 -> 0 | D28: Next quarter with growth
A29: Q3 Estimate (cumulative) | B29: =B27*1.15 -> #REF! | D29: Third quarter projection
A30: Q4 Estimate (cumulative) | B30: =B28*1.15 -> 0 | D30: Fourth quarter projection
A32: DATABASE COST BREAKDOWN | D32: Database technology cost analysis
A34: Vector Database Cost Ratio | B34: =B8/B10*100 -> #REF! | D34: Vector database cost percentage
A35: Graph Database Cost Ratio | B35: =B9/B10*100 -> #REF! | D35: Graph database cost percentage
A36: Traditional Database Cost Ratio | B36: =(B3+B4)/B10*100 -> #REF! | D36: Traditional database cost percentage

Sheet Scenarios
A1: Scenario | B1: Team Size | C1: Sessions/User/Day | D1: Vector Usage Multiplier | E1: Graph Usage Multiplier | F1: Monthly Cost | G1: Cost/User/Month | H1: Notes
A2: Baseline (Current) | B2: 10 | C2: 3 | D2: 1 | E2: 1 | F2: =Calculations!B10 -> #REF! | G2: =F1/B1 -> #VALUE! | H2: Standard sandbox usage pattern
A3: Light Usage | B3: 5 | C3: 2 | D3: 0.5 | E3: 0.3 | F3: =Calculations!B10*0.4 -> #REF! | G3: =F2/B2 -> #REF! | H3: Minimal experimentation
A4: Heavy Usage | B4: 15 | C4: 5 | D4: 1.5 | E4: 1.2 | F4: =Calculations!B10*1.8 -> #REF! | G4: =F3/B3 -> #REF! | H4: Active development phase
A5: Training Event | B5: 25 | C5: 8 | D5: 2 | E5: 1.5 | F5: =Calculations!B10*4.2 -> #REF! | G5: =F4/B4 -> #REF! | H5: Intensive training workshop
A6: Vector Search Heavy | B6: 10 | C6: 6 | D6: 3 | E6: 0.8 | F6: =Calculations!B10*2.1 -> #REF! | G6: =F5/B5 -> #REF! | H6: Heavy vector search workload
A7: Graph Analytics | B7: 8 | C7: 4 | D7: 1 | E7: 3 | F7: =Calculations!B10*1.9 -> #REF! | G7: =F6/B6 -> #REF! | H7: Graph analytics and ML training
A8: RAG + GraphRAG | B8: 12 | C8: 5 | D8: 2.5 | E8: 2 | F8: =Calculations!B10*2.8 -> #REF! | G8: =F7/B7 -> #REF! | H8: Combined RAG and GraphRAG
A9: Production Pilot | B9: 10 | C9: 3 | D9: 1.2 | E9: 1 | F9: =Calculations!B10*1 -> #REF! | G9: =F8/B8 -> #REF! | H9: Pre-production testing

Sheet Documentation
A1: Section | B1: Description | C1: Reference/Link | D1: Action Required
A2: OVERVIEW
A6: Purpose | B6: AWS AgentCore cost model with vector and graph databases | C6: README.md | D6: No action
A7: Scope | B7: Learning, experimentation, PoC development with AI knowledge | C7: AI project charter | D7: No action
A8: Audience | B8: IT architects, finance teams, AI project managers | C8: Stakeholder list | D8: No action
A9: Last Updated | B9: 2025-10-17 | C9: Version control | D9: Update monthly
A11: KEY ASSUMPTIONS
A14: Environment Type | B14: Sandbox/development with vector and graph capabilities | C14: Assumptions worksheet | D14: Validate quarterly
A15: Usage Pattern | B15: Business hours, moderate usage, AI knowledge integration | C15: Usage analysis | D15: Monitor continuously
A16: Geographic Region | B16: US East (N. Virginia) - us-east-1 | C16: AWS region selection | D16: No action
A17: Database Strategy | B17: Hybrid vector + graph database strategy | C17: Database selection guide | D17: Review database choices
A19: WORKSHEET DESCRIPTIONS
A22: Summary | B22: Executive dashboard with enhanced database cost breakdown | C22: Summary worksheet | D22: Update formulas as needed
A23: Assumptions | B23: Project parameters including vector/graph assumptions | C23: Assumptions worksheet | D23: Review monthly
A24: AWS Pricing | B24: Current AWS service pricing including databases | C24: AWS Pricing worksheet | D24: Update quarterly
A25: Bill of Materials | B25: Detailed component quantities with database specifications | C25: Bill of Materials worksheet | D25: Review monthly
A26: Calculations | B26: Cost formulas including database cost ratios | C26: Calculations worksheet | D26: Validate formulas
A27: Scenarios | B27: Multiple usage scenarios including database workloads | C27: Scenarios worksheet | D27: Add new scenarios
A28: Documentation | B28: This enhanced reference guide | C28: Documentation worksheet | D28: Update as needed
A30: VECTOR DATABASE STRATEGY
A34: S3 Vectors | B34: Cost-effective vector storage, 90% savings vs alternatives | C34: S3 Vectors documentation | D34: Evaluate for cost optimization
A35: OpenSearch Service | B35: Hybrid text + vector search, AWS native integration | C35: OpenSearch Service docs | D35: Consider for hybrid workloads
A36: Pinecone | B36: Pure vector search, best performance for vector workloads | C36: Pinecone documentation | D36: Evaluate for performance needs
A37: Use Case Guidance | B37: Use S3 Vectors for cost, OpenSearch for hybrid, Pinecone for performance | C37: Vector database comparison | D37: Document decision criteria
A39: GRAPH DATABASE STRATEGY
A42: Amazon Neptune | B42: Serverless graph database, GraphRAG integration | C42: Neptune documentation | D42: Plan GraphRAG integration
A43: Neo4j on EC2 | B43: Self-managed graph database for custom requirements | C43: Neo4j documentation | D43: Consider for custom graphs
A44: GraphRAG Integration | B44: Knowledge graph RAG for enhanced AI responses | C44: GraphRAG best practices | D44: Implement GraphRAG
A45: Knowledge Graph Design | B45: Entity-relationship modeling for domain knowledge | C45: Knowledge graph design patterns | D45: Design knowledge model
A47: COST OPTIMIZATION TIPS
A50: Same-AZ Placement | B50: Deploy services in same AZ to avoid data transfer costs | C50: AWS Well-Architected Framework | D50: Implement as needed
A51: Vector Storage Optimization | B51: Use S3 Vectors for cold storage, OpenSearch for hot queries | C51: Vector optimization guide | D51: Monitor storage costs
A52: Graph Query Optimization | B52: Optimize graph query patterns and indexing strategies | C52: Graph performance tuning | D52: Optimize query performance
A53: Resource Right-sizing | B53: Size instances based on actual vector/graph workloads | C53: Database monitoring | D53: Monitor and adjust
A54: Scheduled Scaling | B54: Scale down databases during off-hours | C54: Auto Scaling | D54: Configure as needed
A55: Database Selection | B55: Choose appropriate database for workload characteristics | C55: Database selection matrix | D55: Evaluate database fit
A56: Caching Strategy | B56: Implement vector and graph result caching | C56: Caching best practices | D56: Implement as needed
A58: DATA SOURCES
A62: AWS Pricing Calculator | B62: https://calculator.aws/ | C62: AWS Calculator | D62: Bookmark for reference
A63: Vector Database Pricing | B63: Vector database vendor pricing pages | C63: Vector DB pricing | D63: Research pricing models
...
